Workbook

Sheet routine
A1: Start time | C1: Move type | D1: File | E1: Duration | F1: Repeat | G1: Start speed °/s | H1: kP | I1: kI | J1: Notes
A2: 0 | B2: =INT(A2/60000) & ":" & INT(MOD(A2/1000, 60)) & "." & TEXT(INT(MOD(A2/1, 1000)), "000") -> 0:0.000 | C2: start_only | D2: act_salto_p1_opening.csv | E2: =INDEX(movelist!B:B, MATCH($D2, movelist!A:A, 0)) -> 147467 | F2: false | G2: 190 | H2: 50 | I2: 2
A3: 150 | B3: =INT(A3/60000) & ":" & INT(MOD(A3/1000, 60)) & "." & TEXT(INT(MOD(A3/1, 1000)), "000") -> 0:0.150 | C3: movement | D3: act_salto_p1_opening.csv | E3: =INDEX(movelist!B:B, MATCH($D3, movelist!A:A, 0)) -> 147467 | F3: false | G3: 190 | H3: 50 | I3: 2
A4: 500 | B4: =INT(A4/60000) & ":" & INT(MOD(A4/1000, 60)) & "." & TEXT(INT(MOD(A4/1, 1000)), "000") -> 0:0.500 | C4: movement | D4: act_salto_slapstick_pose.csv | E4: =INDEX(movelist!B:B, MATCH($D4, movelist!A:A, 0)) -> 1000 | F4: false | G4: 75 | H4: 0 | I4: 0 | J4: OFF
A5: =A4 + 4000 -> 4500 | B5: =INT(A5/60000) & ":" & INT(MOD(A5/1000, 60)) & "." & TEXT(INT(MOD(A5/1, 1000)), "000") -> 0:4.500 | C5: movement | D5: act_salto_slapstick_pose.csv | E5: =INDEX(movelist!B:B, MATCH($D5, movelist!A:A, 0)) -> 1000 | F5: true | G5: 75 | H5: 0 | I5: 0.15 | J5: Iets spanning zodat benen niet overklappen
A6: =A5+4000 -> 8500 | B6: =INT(A6/60000) & ":" & INT(MOD(A6/1000, 60)) & "." & TEXT(INT(MOD(A6/1, 1000)), "000") -> 0:8.500 | C6: movement | D6: act_salto_slapstick_pose.csv | E6: =INDEX(movelist!B:B, MATCH($D6, movelist!A:A, 0)) -> 1000 | F6: false | G6: 75 | H6: 0 | I6: 0 | J6: OFF
A7: =A6 + 4000 -> 12500 | B7: =INT(A7/60000) & ":" & INT(MOD(A7/1000, 60)) & "." & TEXT(INT(MOD(A7/1, 1000)), "000") -> 0:12.500 | C7: movement | D7: act_salto_slapstick_pose.csv | E7: =INDEX(movelist!B:B, MATCH($D7, movelist!A:A, 0)) -> 1000 | F7: true | G7: 75 | H7: 0 | I7: 0.15 | J7: Iets spanning zodat benen niet overklappen
A8: =A7+4000 -> 16500 | B8: =INT(A8/60000) & ":" & INT(MOD(A8/1000, 60)) & "." & TEXT(INT(MOD(A8/1, 1000)), "000") -> 0:16.500 | C8: movement | D8: act_salto_slapstick_pose.csv | E8: =INDEX(movelist!B:B, MATCH($D8, movelist!A:A, 0)) -> 1000 | F8: false | G8: 75 | H8: 0 | I8: 0 | J8: OFF
A9: =A8 + 4000 -> 20500 | B9: =INT(A9/60000) & ":" & INT(MOD(A9/1000, 60)) & "." & TEXT(INT(MOD(A9/1, 1000)), "000") -> 0:20.500 | C9: movement | D9: act_salto_slapstick_pose.csv | E9: =INDEX(movelist!B:B, MATCH($D9, movelist!A:A, 0)) -> 1000 | F9: true | G9: 75 | H9: 0 | I9: 0.15 | J9: Iets spanning zodat benen niet overklappen
A10: =A9+4000 -> 24500 | B10: =INT(A10/60000) & ":" & INT(MOD(A10/1000, 60)) & "." & TEXT(INT(MOD(A10/1, 1000)), "000") -> 0:24.500 | C10: movement | D10: act_salto_slapstick_pose.csv | E10: =INDEX(movelist!B:B, MATCH($D10, movelist!A:A, 0)) -> 1000 | F10: false | G10: 75 | H10: 0 | I10: 0 | J10: OFF
A11: =A10 + 4000 -> 28500 | B11: =INT(A11/60000) & ":" & INT(MOD(A11/1000, 60)) & "." & TEXT(INT(MOD(A11/1, 1000)), "000") -> 0:28.500 | C11: movement | D11: act_salto_slapstick_pose.csv | E11: =INDEX(movelist!B:B, MATCH($D11, movelist!A:A, 0)) -> 1000 | F11: true | G11: 75 | H11: 0 | I11: 0.15 | J11: Iets spanning zodat benen niet overklappen
A12: =A11+4000 -> 32500 | B12: =INT(A12/60000) & ":" & INT(MOD(A12/1000, 60)) & "." & TEXT(INT(MOD(A12/1, 1000)), "000") -> 0:32.500 | C12: movement | D12: act_salto_slapstick_pose.csv | E12: =INDEX(movelist!B:B, MATCH($D12, movelist!A:A, 0)) -> 1000 | F12: false | G12: 75 | H12: 0 | I12: 0 | J12: OFF
A13: =A12 + 4000 -> 36500 | B13: =INT(A13/60000) & ":" & INT(MOD(A13/1000, 60)) & "." & TEXT(INT(MOD(A13/1, 1000)), "000") -> 0:36.500 | C13: movement | D13: act_salto_slapstick_pose.csv | E13: =INDEX(movelist!B:B, MATCH($D13, movelist!A:A, 0)) -> 1000 | F13: true | G13: 75 | H13: 0 | I13: 0.15 | J13: Iets spanning zodat benen niet overklappen
A14: =A13+4000 -> 40500 | B14: =INT(A14/60000) & ":" & INT(MOD(A14/1000, 60)) & "." & TEXT(INT(MOD(A14/1, 1000)), "000") -> 0:40.500 | C14: movement | D14: act_salto_slapstick_pose.csv | E14: =INDEX(movelist!B:B, MATCH($D14, movelist!A:A, 0)) -> 1000 | F14: false | G14: 75 | H14: 0 | I14: 0 | J14: OFF
A15: =A14 + 4000 -> 44500 | B15: =INT(A15/60000) & ":" & INT(MOD(A15/1000, 60)) & "." & TEXT(INT(MOD(A15/1, 1000)), "000") -> 0:44.500 | C15: movement | D15: act_salto_slapstick_pose.csv | E15: =INDEX(movelist!B:B, MATCH($D15, movelist!A:A, 0)) -> 1000 | F15: true | G15: 75 | H15: 0 | I15: 0.15 | J15: Iets spanning zodat benen niet overklappen
A16: =A15+4000 -> 48500 | B16: =INT(A16/60000) & ":" & INT(MOD(A16/1000, 60)) & "." & TEXT(INT(MOD(A16/1, 1000)), "000") -> 0:48.500 | C16: movement | D16: act_salto_slapstick_pose.csv | E16: =INDEX(movelist!B:B, MATCH($D16, movelist!A:A, 0)) -> 1000 | F16: false | G16: 75 | H16: 0 | I16: 0 | J16: OFF
A17: =A16 + 4000 -> 52500 | B17: =INT(A17/60000) & ":" & INT(MOD(A17/1000, 60)) & "." & TEXT(INT(MOD(A17/1, 1000)), "000") -> 0:52.500 | C17: movement | D17: act_salto_slapstick_pose.csv | E17: =INDEX(movelist!B:B, MATCH($D17, movelist!A:A, 0)) -> 1000 | F17: true | G17: 75 | H17: 0 | I17: 0.15 | J17: Iets spanning zodat benen niet overklappen
A18: =A17+4000 -> 56500 | B18: =INT(A18/60000) & ":" & INT(MOD(A18/1000, 60)) & "." & TEXT(INT(MOD(A18/1, 1000)), "000") -> 0:56.500 | C18: movement | D18: act_salto_slapstick_pose.csv | E18: =INDEX(movelist!B:B, MATCH($D18, movelist!A:A, 0)) -> 1000 | F18: false | G18: 75 | H18: 0 | I18: 0 | J18: OFF
A19: =A18 + 4000 -> 60500 | B19: =INT(A19/60000) & ":" & INT(MOD(A19/1000, 60)) & "." & TEXT(INT(MOD(A19/1, 1000)), "000") -> 1:0.500 | C19: movement | D19: act_salto_slapstick_pose.csv | E19: =INDEX(movelist!B:B, MATCH($D19, movelist!A:A, 0)) -> 1000 | F19: true | G19: 75 | H19: 0 | I19: 0.15 | J19: Iets spanning zodat benen niet overklappen
A20: =A19+4000 -> 64500 | B20: =INT(A20/60000) & ":" & INT(MOD(A20/1000, 60)) & "." & TEXT(INT(MOD(A20/1, 1000)), "000") -> 1:4.500 | C20: movement | D20: act_salto_slapstick_pose.csv | E20: =INDEX(movelist!B:B, MATCH($D20, movelist!A:A, 0)) -> 1000 | F20: false | G20: 75 | H20: 0 | I20: 0 | J20: OFF
A21: =A20 + 4000 -> 68500 | B21: =INT(A21/60000) & ":" & INT(MOD(A21/1000, 60)) & "." & TEXT(INT(MOD(A21/1, 1000)), "000") -> 1:8.500 | C21: movement | D21: act_salto_slapstick_pose.csv | E21: =INDEX(movelist!B:B, MATCH($D21, movelist!A:A, 0)) -> 1000 | F21: true | G21: 75 | H21: 0 | I21: 0.15 | J21: Iets spanning zodat benen niet overklappen
A22: =A21+4000 -> 72500 | B22: =INT(A22/60000) & ":" & INT(MOD(A22/1000, 60)) & "." & TEXT(INT(MOD(A22/1, 1000)), "000") -> 1:12.500 | C22: movement | D22: act_salto_slapstick_pose.csv | E22: =INDEX(movelist!B:B, MATCH($D22, movelist!A:A, 0)) -> 1000 | F22: false | G22: 75 | H22: 0 | I22: 0 | J22: OFF
A23: =A22 + 4000 -> 76500 | B23: =INT(A23/60000) & ":" & INT(MOD(A23/1000, 60)) & "." & TEXT(INT(MOD(A23/1, 1000)), "000") -> 1:16.500 | C23: movement | D23: act_salto_slapstick_pose.csv | E23: =INDEX(movelist!B:B, MATCH($D23, movelist!A:A, 0)) -> 1000 | F23: true | G23: 75 | H23: 0 | I23: 0.15 | J23: Iets spanning zodat benen niet overklappen
A24: =A23+4000 -> 80500 | B24: =INT(A24/60000) & ":" & INT(MOD(A24/1000, 60)) & "." & TEXT(INT(MOD(A24/1, 1000)), "000") -> 1:20.500 | C24: movement | D24: act_salto_slapstick_pose.csv | E24: =INDEX(movelist!B:B, MATCH($D24, movelist!A:A, 0)) -> 1000 | F24: false | G24: 75 | H24: 0 | I24: 0 | J24: OFF
A25: =A24 + 4000 -> 84500 | B25: =INT(A25/60000) & ":" & INT(MOD(A25/1000, 60)) & "." & TEXT(INT(MOD(A25/1, 1000)), "000") -> 1:24.500 | C25: movement | D25: act_salto_slapstick_pose.csv | E25: =INDEX(movelist!B:B, MATCH($D25, movelist!A:A, 0)) -> 1000 | F25: true | G25: 75 | H25: 0 | I25: 0.15 | J25: Iets spanning zodat benen niet overklappen
A26: =A25+4000 -> 88500 | B26: =INT(A26/60000) & ":" & INT(MOD(A26/1000, 60)) & "." & TEXT(INT(MOD(A26/1, 1000)), "000") -> 1:28.500 | C26: movement | D26: act_salto_slapstick_pose.csv | E26: =INDEX(movelist!B:B, MATCH($D26, movelist!A:A, 0)) -> 1000 | F26: false | G26: 75 | H26: 0 | I26: 0 | J26: OFF
A27: =A26 + 4000 -> 92500 | B27: =INT(A27/60000) & ":" & INT(MOD(A27/1000, 60)) & "." & TEXT(INT(MOD(A27/1, 1000)), "000") -> 1:32.500 | C27: movement | D27: act_salto_slapstick_pose.csv | E27: =INDEX(movelist!B:B, MATCH($D27, movelist!A:A, 0)) -> 1000 | F27: true | G27: 75 | H27: 0 | I27: 0.15 | J27: Iets spanning zodat benen niet overklappen
A28: =A27+4000 -> 96500 | B28: =INT(A28/60000) & ":" & INT(MOD(A28/1000, 60)) & "." & TEXT(INT(MOD(A28/1, 1000)), "000") -> 1:36.500 | C28: movement | D28: act_salto_slapstick_pose.csv | E28: =INDEX(movelist!B:B, MATCH($D28, movelist!A:A, 0)) -> 1000 | F28: false | G28: 75 | H28: 0 | I28: 0 | J28: OFF
A29: =A28 + 4000 -> 100500 | B29: =INT(A29/60000) & ":" & INT(MOD(A29/1000, 60)) & "." & TEXT(INT(MOD(A29/1, 1000)), "000") -> 1:40.500 | C29: movement | D29: act_salto_slapstick_pose.csv | E29: =INDEX(movelist!B:B, MATCH($D29, movelist!A:A, 0)) -> 1000 | F29: true | G29: 75 | H29: 0 | I29: 0.15 | J29: Iets spanning zodat benen niet overklappen
A30: =A29+4000 -> 104500 | B30: =INT(A30/60000) & ":" & INT(MOD(A30/1000, 60)) & "." & TEXT(INT(MOD(A30/1, 1000)), "000") -> 1:44.500 | C30: movement | D30: act_salto_slapstick_pose.csv | E30: =INDEX(movelist!B:B, MATCH($D30, movelist!A:A, 0)) -> 1000 | F30: false | G30: 75 | H30: 0 | I30: 0 | J30: OFF
A31: =A30 + 4000 -> 108500 | B31: =INT(A31/60000) & ":" & INT(MOD(A31/1000, 60)) & "." & TEXT(INT(MOD(A31/1, 1000)), "000") -> 1:48.500 | C31: movement | D31: act_salto_slapstick_pose.csv | E31: =INDEX(movelist!B:B, MATCH($D31, movelist!A:A, 0)) -> 1000 | F31: true | G31: 75 | H31: 0 | I31: 0.15 | J31: Iets spanning zodat benen niet overklappen
A32: =A31+4000 -> 112500 | B32: =INT(A32/60000) & ":" & INT(MOD(A32/1000, 60)) & "." & TEXT(INT(MOD(A32/1, 1000)), "000") -> 1:52.500 | C32: movement | D32: act_salto_slapstick_pose.csv | E32: =INDEX(movelist!B:B, MATCH($D32, movelist!A:A, 0)) -> 1000 | F32: false | G32: 75 | H32: 0 | I32: 0 | J32: OFF
A33: =A32 + 4000 -> 116500 | B33: =INT(A33/60000) & ":" & INT(MOD(A33/1000, 60)) & "." & TEXT(INT(MOD(A33/1, 1000)), "000") -> 1:56.500 | C33: movement | D33: act_salto_slapstick_pose.csv | E33: =INDEX(movelist!B:B, MATCH($D33, movelist!A:A, 0)) -> 1000 | F33: true | G33: 75 | H33: 0 | I33: 0.15 | J33: Iets spanning zodat benen niet overklappen
A34: =A33+4000 -> 120500 | B34: =INT(A34/60000) & ":" & INT(MOD(A34/1000, 60)) & "." & TEXT(INT(MOD(A34/1, 1000)), "000") -> 2:0.500 | C34: movement | D34: act_salto_slapstick_pose.csv | E34: =INDEX(movelist!B:B, MATCH($D34, movelist!A:A, 0)) -> 1000 | F34: false | G34: 75 | H34: 0 | I34: 0 | J34: OFF
A35: =A34 + 4000 -> 124500 | B35: =INT(A35/60000) & ":" & INT(MOD(A35/1000, 60)) & "." & TEXT(INT(MOD(A35/1, 1000)), "000") -> 2:4.500 | C35: movement | D35: act_salto_slapstick_pose.csv | E35: =INDEX(movelist!B:B, MATCH($D35, movelist!A:A, 0)) -> 1000 | F35: true | G35: 75 | H35: 0 | I35: 0.15 | J35: Iets spanning zodat benen niet overklappen
A36: =A35+4000 -> 128500 | B36: =INT(A36/60000) & ":" & INT(MOD(A36/1000, 60)) & "." & TEXT(INT(MOD(A36/1, 1000)), "000") -> 2:8.500 | C36: movement | D36: act_salto_slapstick_pose.csv | E36: =INDEX(movelist!B:B, MATCH($D36, movelist!A:A, 0)) -> 1000 | F36: false | G36: 75 | H36: 0 | I36: 0 | J36: OFF
A37: =A36 + 4000 -> 132500 | B37: =INT(A37/60000) & ":" & INT(MOD(A37/1000, 60)) & "." & TEXT(INT(MOD(A37/1, 1000)), "000") -> 2:12.500 | C37: movement | D37: act_salto_slapstick_pose.csv | E37: =INDEX(movelist!B:B, MATCH($D37, movelist!A:A, 0)) -> 1000 | F37: true | G37: 75 | H37: 0 | I37: 0.15 | J37: Iets spanning zodat benen niet overklappen
A38: =A37+4000 -> 136500 | B38: =INT(A38/60000) & ":" & INT(MOD(A38/1000, 60)) & "." & TEXT(INT(MOD(A38/1, 1000)), "000") -> 2:16.500 | C38: movement | D38: act_salto_slapstick_pose.csv | E38: =INDEX(movelist!B:B, MATCH($D38, movelist!A:A, 0)) -> 1000 | F38: false | G38: 75 | H38: 0 | I38: 0 | J38: OFF
A39: =A38 + 4000 -> 140500 | B39: =INT(A39/60000) & ":" & INT(MOD(A39/1000, 60)) & "." & TEXT(INT(MOD(A39/1, 1000)), "000") -> 2:20.500 | C39: movement | D39: act_salto_slapstick_pose.csv | E39: =INDEX(movelist!B:B, MATCH($D39, movelist!A:A, 0)) -> 1000 | F39: true | G39: 75 | H39: 0 | I39: 0.15 | J39: Iets spanning zodat benen niet overklappen
A40: =A39+4000 -> 144500 | B40: =INT(A40/60000) & ":" & INT(MOD(A40/1000, 60)) & "." & TEXT(INT(MOD(A40/1, 1000)), "000") -> 2:24.500 | C40: movement | D40: act_salto_slapstick_pose.csv | E40: =INDEX(movelist!B:B, MATCH($D40, movelist!A:A, 0)) -> 1000 | F40: false | G40: 75 | H40: 0 | I40: 0 | J40: OFF
...

Sheet movelist
A2: acro2_backflip.csv | B2: 7500
A3: acro2_backflip_pause.csv | B3: 13500
A4: acro2_backflip_pause_v2.csv | B4: 17033
A5: acro_cannonball_f2h.csv | B5: 8467
A6: acro_contra_rolldown.csv | B6: 19733
A7: acro_curbet.csv | B7: 13800
A8: acro_leg_exchange_L2R.csv | B8: 13033
A9: acro_podcheska.csv | B9: 7500
A10: acro_podzieska_contra.csv | B10: 8233
A11: act_explanation_01_wave.csv | B11: 178167
A12: act_explanation_02_schrik.csv | B12: 60567
A13: act_explanation_03_schouders.csv | B13: 74033
... A161: act_salto_slapstick_pose.csv | B161: 1000
